<?xml version='1.0' encoding='UTF-8'?>
<!--[GENERATED XML-FILE]-->
<robot name="robot_frame">
  <material name="BlueOne">
    <color rgba="0.0 0.0 1.0 1.0"/>
  </material>
  <material name="RedOne">
    <color rgba="1.0 0.0 0.0 1.0"/>
  </material>
  <material name="WhiteOne">
    <color rgba="1.0 1.0 1.0 1.0"/>
  </material>
  <material name="YellowOne">
    <color rgba="0.651 0.67 0.114 1.0"/>
  </material>
  <material name="BlackOne">
    <color rgba="0 0 0 1.0"/>
  </material>
  <material name="OrangeOne">
    <color rgba="0.96 0.613 0.365 1.0"/>
  </material>
  <material name="PurpleOne">
    <color rgba="0.633 0.114 0.67 1.0"/>
  </material>
  <material name="TurquoiseOne">
    <color rgba="0.114 0.67 0.642 1.0"/>
  </material>
  <material name="GreenOne">
    <color rgba="0.653 0.96 0.684 1.0"/>
  </material>
  <material name="IndigoOne">
    <color rgba="0.468 0.408 0.77 1.0"/>
  </material>
  <material name="GreyOne">
    <color rgba="0.75 0.7 0.8 1.0"/>
  </material>
  <material name="GreyTransparentOne">
    <color rgba="0.754 0.79 0.82 1.0"/>
  </material>
  <link name="front_axle">
    <visual>
      <origin rpy="0 0 0" xyz="0 0 0"/>
      <geometry>
        <cylinder length="0.51" radius="0.01"/>
      </geometry>
      <material name="WhiteOne"/>
    </visual>
    <collision>
      <origin rpy="0 0 0" xyz="0 0 0"/>
      <geometry>
        <cylinder length="0.51" radius="0.01"/>
      </geometry>
    </collision>
    <inertial>
      <origin rpy="0 0 0" xyz="0 0 0"/>
      <mass value="0.015"/>
      <inertia ixx="0.0003255" ixy="0.0" ixz="0.0" iyy="0.0003255" iyz="0.0" izz="7.5e-07"/>
    </inertial>
  </link>
  <link name="back_axle">
    <visual>
      <origin rpy="0 0 0" xyz="0 0 0"/>
      <geometry>
        <cylinder length="0.51" radius="0.01"/>
      </geometry>
      <material name="WhiteOne"/>
    </visual>
    <collision>
      <origin rpy="0 0 0" xyz="0 0 0"/>
      <geometry>
        <cylinder length="0.51" radius="0.01"/>
      </geometry>
    </collision>
    <inertial>
      <origin rpy="0 0 0" xyz="0 0 0"/>
      <mass value="0.015"/>
      <inertia ixx="0.0003255" ixy="0.0" ixz="0.0" iyy="0.0003255" iyz="0.0" izz="7.5e-07"/>
    </inertial>
  </link>
  <link name="front_left_wheel">
    <visual>
      <origin rpy="3.141592653589793 0 0" xyz="0 0 0"/>
      <geometry>
        <cylinder length="0.04" radius="0.0923076923076923"/>
      </geometry>
      <material name="IndigoOne"/>
    </visual>
    <collision>
      <origin rpy="0 0 0" xyz="0 0 0"/>
      <geometry>
        <cylinder length="0.04" radius="0.0923076923076923"/>
      </geometry>
    </collision>
    <inertial>
      <origin rpy="0 0 0" xyz="0 0 0"/>
      <mass value="2"/>
      <inertia ixx="0.0045270216962524645" ixy="0.0" ixz="0.0" iyy="0.0045270216962524645" iyz="0.0" izz="0.008520710059171595"/>
    </inertial>
  </link>
  <gazebo reference="front_left_wheel">
    <visual>
      <material>
        <ambient>0.1 0.1 0.1 1</ambient>
        <diffuse>0.1 0.1 0.2 1</diffuse>
        <specular>0 0 0 0</specular>
        <emissive>0 0 0 1</emissive>
      </material>
    </visual>
  </gazebo>
  <link name="front_right_wheel">
    <visual>
      <origin rpy="-3.141592653589793 0 0" xyz="0 0 0"/>
      <geometry>
        <cylinder length="0.04" radius="0.0923076923076923"/>
      </geometry>
      <material name="IndigoOne"/>
    </visual>
    <collision>
      <origin rpy="0 0 0" xyz="0 0 0"/>
      <geometry>
        <cylinder length="0.04" radius="0.0923076923076923"/>
      </geometry>
    </collision>
    <inertial>
      <origin rpy="0 0 0" xyz="0 0 0"/>
      <mass value="2"/>
      <inertia ixx="0.0045270216962524645" ixy="0.0" ixz="0.0" iyy="0.0045270216962524645" iyz="0.0" izz="0.008520710059171595"/>
    </inertial>
  </link>
  <gazebo reference="front_right_wheel">
    <visual>
      <material>
        <ambient>0.1 0.1 0.1 1</ambient>
        <diffuse>0.1 0.1 0.2 1</diffuse>
        <specular>0 0 0 0</specular>
        <emissive>0 0 0 1</emissive>
      </material>
    </visual>
  </gazebo>
  <link name="back_left_wheel">
    <visual>
      <origin rpy="3.141592653589793 0 0" xyz="0 0 0"/>
      <geometry>
        <cylinder length="0.04" radius="0.0923076923076923"/>
      </geometry>
      <material name="IndigoOne"/>
    </visual>
    <collision>
      <origin rpy="0 0 0" xyz="0 0 0"/>
      <geometry>
        <cylinder length="0.04" radius="0.0923076923076923"/>
      </geometry>
    </collision>
    <inertial>
      <origin rpy="0 0 0" xyz="0 0 0"/>
      <mass value="2"/>
      <inertia ixx="0.0045270216962524645" ixy="0.0" ixz="0.0" iyy="0.0045270216962524645" iyz="0.0" izz="0.008520710059171595"/>
    </inertial>
  </link>
  <gazebo reference="back_left_wheel">
    <visual>
      <material>
        <ambient>0.1 0.1 0.1 1</ambient>
        <diffuse>0.1 0.1 0.2 1</diffuse>
        <specular>0 0 0 0</specular>
        <emissive>0 0 0 1</emissive>
      </material>
    </visual>
  </gazebo>
  <link name="back_right_wheel">
    <visual>
      <origin rpy="-3.141592653589793 0 0" xyz="0 0 0"/>
      <geometry>
        <cylinder length="0.04" radius="0.0923076923076923"/>
      </geometry>
      <material name="IndigoOne"/>
    </visual>
    <collision>
      <origin rpy="0 0 0" xyz="0 0 0"/>
      <geometry>
        <cylinder length="0.04" radius="0.0923076923076923"/>
      </geometry>
    </collision>
    <inertial>
      <origin rpy="0 0 0" xyz="0 0 0"/>
      <mass value="2"/>
      <inertia ixx="0.0045270216962524645" ixy="0.0" ixz="0.0" iyy="0.0045270216962524645" iyz="0.0" izz="0.008520710059171595"/>
    </inertial>
  </link>
  <gazebo reference="back_right_wheel">
    <visual>
      <material>
        <ambient>0.1 0.1 0.1 1</ambient>
        <diffuse>0.1 0.1 0.2 1</diffuse>
        <specular>0 0 0 0</specular>
        <emissive>0 0 0 1</emissive>
      </material>
    </visual>
  </gazebo>
  <link name="box_panel_back">
    <visual>
      <origin rpy="0 0 1.5707963267948966" xyz="0 0 0.15"/>
      <geometry>
        <box size="0.4 0.03 0.3"/>
      </geometry>
      <material name="YellowOne"/>
    </visual>
    <collision>
      <origin rpy="0 0 1.5707963267948966" xyz="0 0 0.15"/>
      <geometry>
        <box size="0.4 0.03 0.3"/>
      </geometry>
    </collision>
    <inertial>
      <mass value="1.6666666666666667"/>
      <inertia ixx="0.034722222222222224" ixy="0.0" ixz="0.0" iyy="0.012624999999999999" iyz="0.0" izz="0.02234722222222223"/>
      <origin xyz=".0 .0 0.09999999999999999"/>
    </inertial>
  </link>
  <gazebo reference="box_panel_back">
    <visual>
      <material>
        <script>
          <uri>file:///home/osin/dev_ws/install/robot_frame/share/robot_frame/description/resources/sticker/bg_sticker.material</uri>
          <name>vc_robot/bg_sticker</name>
        </script>
      </material>
    </visual>
  </gazebo>
  <link name="box_panel_front">
    <visual>
      <origin rpy="0 0 1.5707963267948966" xyz="-0.015 0 0.15"/>
      <geometry>
        <box size="0.4 0.03 0.3"/>
      </geometry>
      <material name="YellowOne"/>
    </visual>
    <collision>
      <origin rpy="0 0 1.5707963267948966" xyz="-0.015 0 0.15"/>
      <geometry>
        <box size="0.4 0.03 0.3"/>
      </geometry>
    </collision>
    <inertial>
      <mass value="1.6666666666666667"/>
      <inertia ixx="0.034722222222222224" ixy="0.0" ixz="0.0" iyy="0.012624999999999999" iyz="0.0" izz="0.02234722222222223"/>
      <origin xyz="-0.015 .0 0.09999999999999999"/>
    </inertial>
  </link>
  <gazebo reference="box_panel_back">
    <visual>
      <material>
        <script>
          <uri>file:///home/osin/dev_ws/install/robot_frame/share/robot_frame/description/resources/sticker/bg_sticker.material</uri>
          <name>vc_robot/bg_sticker</name>
        </script>
      </material>
    </visual>
  </gazebo>
  <link name="box_panel_left">
    <visual>
      <origin rpy=".0 .0 1.5707963267948966" xyz=".0 -0.015 0.15"/>
      <geometry>
        <box size="0.03 0.3778378378378378 0.3"/>
      </geometry>
      <material name="YellowOne"/>
    </visual>
    <collision>
      <origin rpy=".0 .0 1.5707963267948966" xyz=".0 -0.015 0.15"/>
      <geometry>
        <box size="0.03 0.3778378378378378 0.3"/>
      </geometry>
    </collision>
    <inertial>
      <mass value="1.6666666666666667"/>
      <inertia ixx="0.012624999999999999" ixy="0.0" ixz="0.0" iyy="0.032327976625273924" iyz="0.0" izz="0.019952976625273924"/>
      <origin xyz=".0 -0.015 0.09999999999999999"/>
    </inertial>
  </link>
  <gazebo reference="box_panel_left">
    <visual>
      <material>
        <script>
          <uri>file:///home/osin/dev_ws/install/robot_frame/share/robot_frame/description/resources/sticker/sticker.material</uri>
          <name>vc_robot/sticker</name>
        </script>
      </material>
    </visual>
  </gazebo>
  <link name="box_panel_right">
    <visual>
      <origin rpy=".0 .0 1.5707963267948966" xyz=".0 0.015 0.15"/>
      <geometry>
        <box size="0.03 0.3778378378378378 0.3"/>
      </geometry>
      <material name="YellowOne"/>
    </visual>
    <collision>
      <origin rpy=".0 .0 1.5707963267948966" xyz=".0 0.015 0.15"/>
      <geometry>
        <box size="0.03 0.3778378378378378 0.3"/>
      </geometry>
    </collision>
    <inertial>
      <mass value="1.6666666666666667"/>
      <inertia ixx="0.012624999999999999" ixy="0.0" ixz="0.0" iyy="0.032327976625273924" iyz="0.0" izz="0.019952976625273924"/>
      <origin xyz=".0 0.015 0.09999999999999999"/>
    </inertial>
  </link>
  <gazebo reference="box_panel_right">
    <visual>
      <material>
        <script>
          <uri>file:///home/osin/dev_ws/install/robot_frame/share/robot_frame/description/resources/sticker/sticker.material</uri>
          <name>vc_robot/sticker</name>
        </script>
      </material>
    </visual>
  </gazebo>
  <link name="box_panel_top">
    <visual>
      <origin rpy=".0 .0 1.5707963267948966" xyz="0.07297297297297296 .0 0.0075"/>
      <geometry>
        <box size="0.4 0.14594594594594593 0.015"/>
      </geometry>
      <material name="YellowOne"/>
    </visual>
    <collision>
      <origin rpy=".0 .0 1.5707963267948966" xyz="0.07297297297297296 .0 0.0075"/>
      <geometry>
        <box size="0.4 0.14594594594594593 0.015"/>
      </geometry>
    </collision>
    <inertial>
      <mass value="0.5555555555555556"/>
      <inertia ixx="0.007417824074074075" ixy="0.0" ixz="0.0" iyy="0.000996537923058193" iyz="0.0" izz="0.008393528663798935"/>
      <origin rpy=".0 .0 1.5707963267948966" xyz="0.07297297297297296 .0 .0"/>
    </inertial>
  </link>
  <link name="hinge_cover">
    <visual>
      <origin rpy="0 0 1.5707963267948966" xyz="0 0 0"/>
      <geometry>
        <cylinder length="0.4" radius="0.02"/>
      </geometry>
      <material name="GreenOne"/>
    </visual>
    <collision>
      <geometry>
        <cylinder length="0.4" radius="0.02"/>
      </geometry>
    </collision>
    <inertial>
      <origin rpy="0 0 0" xyz="0 0 0"/>
      <mass value="0.2"/>
      <inertia ixx="0.002686666666666667" ixy="0.0" ixz="0.0" iyy="0.002686666666666667" iyz="0.0" izz="4e-05"/>
    </inertial>
  </link>
  <link name="box_cover">
    <visual>
      <origin rpy=".0 .0 1.5707963267948966" xyz="0.13594594594594595 .0 .0"/>
      <geometry>
        <box size="0.4 0.2718918918918919 0.03"/>
      </geometry>
      <material name="GreenOne"/>
    </visual>
    <collision>
      <origin rpy=".0 .0 1.5707963267948966" xyz="0.13594594594594595 .0 .0"/>
      <geometry>
        <box size="0.4 0.2718918918918919 0.03"/>
      </geometry>
    </collision>
    <inertial>
      <mass value="0.5555555555555556"/>
      <inertia ixx="0.007449074074074076" ixy="0.0" ixz="0.0" iyy="0.0034641296702107513" iyz="0.0" izz="0.010829870410951493"/>
      <origin rpy=".0 .0 1.5707963267948966" xyz="0.13594594594594595 .0 .0"/>
    </inertial>
  </link>
  <link name="box_gripper_left">
    <visual>
      <origin rpy="1.5707963267948966 .0 .0"/>
      <geometry>
        <cylinder length="0.01" radius="0.016530612244897956"/>
      </geometry>
      <material name="YellowOne"/>
    </visual>
    <collision>
      <origin/>
      <geometry>
        <cylinder length="0.01" radius="0.016530612244897956"/>
      </geometry>
    </collision>
    <inertial>
      <origin rpy="1.5707963267948966 .0 .0"/>
      <mass value="0.33333333333333337"/>
      <inertia ixx="2.5549539543708636e-05" ixy="0.0" ixz="0.0" iyy="2.5549539543708636e-05" iyz="0.0" izz="4.5543523531861716e-05"/>
    </inertial>
  </link>
  <link name="box_gripper_holder_left">
    <visual>
      <origin rpy="1.5707963267948966 0 0" xyz="0 0 0"/>
      <geometry>
        <cylinder length="0.015" radius="0.013775510204081631"/>
      </geometry>
      <material name="BlueOne"/>
    </visual>
    <collision>
      <origin rpy="0 0 0" xyz="0 0 0"/>
      <geometry>
        <cylinder length="0.015" radius="0.013775510204081631"/>
      </geometry>
    </collision>
    <inertial>
      <origin rpy="0 0 0" xyz="0 0 0"/>
      <mass value="0.33333333333333337"/>
      <inertia ixx="2.20637234485631e-05" ixy="0.0" ixz="0.0" iyy="2.20637234485631e-05" iyz="0.0" izz="3.162744689712619e-05"/>
    </inertial>
  </link>
  <gazebo reference="box_gripper_holder_left">
    <visual>
      <material>
        <ambient>0.5 0.5 0.5 1.0</ambient>
        <diffuse>0.56666695 0.56666695 0.56666695 1.0</diffuse>
        <specular>0.6000003 0.6000003 0.6000003 1.0</specular>
      </material>
    </visual>
  </gazebo>
  <link name="box_gripper_right">
    <visual>
      <origin rpy="1.5707963267948966 .0 .0"/>
      <geometry>
        <cylinder length="0.01" radius="0.016530612244897956"/>
      </geometry>
      <material name="YellowOne"/>
    </visual>
    <collision>
      <origin/>
      <geometry>
        <cylinder length="0.01" radius="0.016530612244897956"/>
      </geometry>
    </collision>
    <inertial>
      <origin rpy="1.5707963267948966 .0 .0"/>
      <mass value="0.33333333333333337"/>
      <inertia ixx="2.5549539543708636e-05" ixy="0.0" ixz="0.0" iyy="2.5549539543708636e-05" iyz="0.0" izz="4.5543523531861716e-05"/>
    </inertial>
  </link>
  <link name="box_gripper_holder_right">
    <visual>
      <origin rpy="1.5707963267948966 0 0" xyz="0 0 0"/>
      <geometry>
        <cylinder length="0.015" radius="0.013775510204081631"/>
      </geometry>
      <material name="BlueOne"/>
    </visual>
    <collision>
      <origin rpy="0 0 0" xyz="0 0 0"/>
      <geometry>
        <cylinder length="0.015" radius="0.013775510204081631"/>
      </geometry>
    </collision>
    <inertial>
      <origin rpy="0 0 0" xyz="0 0 0"/>
      <mass value="0.33333333333333337"/>
      <inertia ixx="2.20637234485631e-05" ixy="0.0" ixz="0.0" iyy="2.20637234485631e-05" iyz="0.0" izz="3.162744689712619e-05"/>
    </inertial>
  </link>
  <gazebo reference="box_gripper_holder_right">
    <visual>
      <material>
        <ambient>0.5 0.5 0.5 1.0</ambient>
        <diffuse>0.56666695 0.56666695 0.56666695 1.0</diffuse>
        <specular>0.6000003 0.6000003 0.6000003 1.0</specular>
      </material>
    </visual>
  </gazebo>
  <link name="hood_left">
    <visual>
      <origin rpy="0 0 1.5707963267948966" xyz="0 -0.015 0.1"/>
      <geometry>
        <box size="0.03 0.16216216216216214 0.2"/>
      </geometry>
      <material name="OrangeOne"/>
    </visual>
    <collision>
      <origin rpy="0 0 1.5707963267948966" xyz="0 -0.015 0.1"/>
      <geometry>
        <box size="0.03 0.16216216216216214 0.2"/>
      </geometry>
    </collision>
    <inertial>
      <mass value="1.25"/>
      <inertia ixx="0.004260416666666667" ixy="0.0" ixz="0.0" iyy="0.006905892378865352" iyz="0.0" izz="0.0028329757121986843"/>
      <origin rpy=".0 .0 .0" xyz=".0 .0 0.06666666666666667"/>
    </inertial>
  </link>
  <link name="hood_right">
    <visual>
      <origin rpy=".0 .0 1.5707963267948966" xyz="0 0.015 0.1"/>
      <geometry>
        <box size="0.03 0.16216216216216214 0.2"/>
      </geometry>
      <material name="OrangeOne"/>
    </visual>
    <collision>
      <origin rpy=".0 .0 1.5707963267948966" xyz="0 0.015 0.1"/>
      <geometry>
        <box size="0.03 0.16216216216216214 0.2"/>
      </geometry>
    </collision>
    <inertial>
      <mass value="1.25"/>
      <inertia ixx="0.004260416666666667" ixy="0.0" ixz="0.0" iyy="0.006905892378865352" iyz="0.0" izz="0.0028329757121986843"/>
      <origin rpy=".0 .0 .0" xyz=".0 0.015 0.06666666666666667"/>
    </inertial>
  </link>
  <link name="hood_front">
    <visual>
      <origin rpy="0 0 1.5707963267948966" xyz="-0.015 0 0.1"/>
      <geometry>
        <box size="0.4 0.03 0.2"/>
      </geometry>
      <material name="OrangeOne"/>
    </visual>
    <collision>
      <origin rpy="0 0 1.5707963267948966" xyz="-0.015 0 0.1"/>
      <geometry>
        <box size="0.4 0.03 0.2"/>
      </geometry>
    </collision>
    <inertial>
      <mass value="1.25"/>
      <inertia ixx="0.020833333333333336" ixy="0.0" ixz="0.0" iyy="0.004260416666666667" iyz="0.0" izz="0.01676041666666667"/>
      <origin rpy=".0 .0 .0" xyz="-0.015 .0 0.06666666666666667"/>
    </inertial>
  </link>
  <link name="hood_top">
    <visual>
      <origin rpy=".0 .0 1.5707963267948966" xyz="0.040540540540540536 .0 -0.015"/>
      <geometry>
        <box size="0.4 0.08108108108108107 0.03"/>
      </geometry>
      <material name="OrangeOne"/>
    </visual>
    <collision>
      <origin rpy=".0 .0 1.5707963267948966" xyz="0.040540540540540536 .0 -0.015"/>
      <geometry>
        <box size="0.4 0.08108108108108107 0.03"/>
      </geometry>
    </collision>
    <inertial>
      <mass value="0.625"/>
      <inertia ixx="0.008380208333333335" ixy="0.0" ixz="0.0" iyy="0.0003892782140248355" iyz="0.0" izz="0.008675736547358169"/>
      <origin rpy=".0 .0 1.5707963267948966" xyz="0.040540540540540536 .0 .0"/>
    </inertial>
  </link>
  <link name="hood_baffle">
    <visual>
      <origin rpy="-0.6283185307179586 .0 1.5707963267948966" xyz=".0 .0 .0"/>
      <geometry>
        <box size="0.4 0.015 0.1532127335089249"/>
      </geometry>
      <material name="GreyTransparentOne"/>
    </visual>
    <collision>
      <origin rpy="-0.6283185307179586 .0 1.5707963267948966" xyz=".0 .0 .0"/>
      <geometry>
        <box size="0.4 0.015 0.1532127335089249"/>
      </geometry>
    </collision>
    <inertial>
      <mass value="0.4166666666666667"/>
      <inertia ixx="0.006370629920461003" ixy="0.0" ixz="0.0" iyy="0.0008228868649054457" iyz="0.0" izz="0.005563368055555557"/>
      <origin xyz="0.015 .0 .0"/>
    </inertial>
  </link>
  <link name="box_ladle_front">
    <visual>
      <origin rpy="0 0 1.5707963267948966" xyz="0 0 0"/>
      <geometry>
        <box size="0.34 0.015 0.06666666666666667"/>
      </geometry>
      <material name="GreenOne"/>
    </visual>
    <collision>
      <origin rpy="0 0 1.5707963267948966" xyz="0 0 0"/>
      <geometry>
        <box size="0.34 0.015 0.06666666666666667"/>
      </geometry>
    </collision>
    <inertial>
      <mass value="0.33333333333333337"/>
      <inertia ixx="0.003334567901234569" ixy="0.0" ixz="0.0" iyy="0.0001297067901234568" iyz="0.0" izz="0.0032173611111111122"/>
      <origin xyz="0 0 0"/>
    </inertial>
  </link>
  <link name="box_bracket_holder_left">
    <visual>
      <origin rpy="0 0 0" xyz="0 0 0"/>
      <geometry>
        <box size="0.03 0.03 0.03"/>
      </geometry>
      <material name="RedOne"/>
    </visual>
    <collision>
      <origin rpy="0 0 0" xyz="0 0 0"/>
      <geometry>
        <box size="0.03 0.03 0.03"/>
      </geometry>
    </collision>
    <inertial>
      <mass value="0.16666666666666669"/>
      <inertia ixx="2.5e-05" ixy="0.0" ixz="0.0" iyy="2.5e-05" iyz="0.0" izz="2.5e-05"/>
      <origin xyz=".0 .0 .0"/>
    </inertial>
  </link>
  <link name="box_bracket_holder_right">
    <visual>
      <origin rpy="0 0 0" xyz="0 0 0"/>
      <geometry>
        <box size="0.03 0.03 0.03"/>
      </geometry>
      <material name="RedOne"/>
    </visual>
    <collision>
      <origin rpy="0 0 0" xyz="0 0 0"/>
      <geometry>
        <box size="0.03 0.03 0.03"/>
      </geometry>
    </collision>
    <inertial>
      <mass value="0.16666666666666669"/>
      <inertia ixx="2.5e-05" ixy="0.0" ixz="0.0" iyy="2.5e-05" iyz="0.0" izz="2.5e-05"/>
      <origin rpy=".0 .0 .0" xyz=".0 .0 .0"/>
    </inertial>
  </link>
  <link name="front_lidar_box">
    <visual>
      <origin rpy="0 0.7853981633974483 0"/>
      <geometry>
        <box size="0.03 0.03 0.03"/>
      </geometry>
      <material name="GreyOne"/>
    </visual>
    <collision>
      <geometry>
        <box size="0.03 0.03 0.03"/>
      </geometry>
    </collision>
    <inertial>
      <origin xyz="0 0 0"/>
      <mass value="0.05"/>
      <inertia ixx="7.499999999999999e-06" ixy="0.0" ixz="0.0" iyy="7.499999999999999e-06" iyz="0.0" izz="7.499999999999999e-06"/>
    </inertial>
  </link>
  <link name="front_lidar_led">
    <visual>
      <origin xyz="0.0075 0 0.015"/>
      <geometry>
        <sphere radius="0.006"/>
      </geometry>
      <material name="RedOne"/>
    </visual>
    <collision>
      <geometry>
        <sphere radius="0.006"/>
      </geometry>
    </collision>
    <inertial>
      <origin/>
      <mass value="0.001"/>
      <inertia ixx="0.001" ixy="0.0" ixz="0.0" iyy="0.0" iyz="0.0" izz="0.0"/>
    </inertial>
  </link>
  <joint name="front_lidar_led_joint" type="fixed">
    <parent link="front_lidar_box"/>
    <child link="front_lidar_led"/>
  </joint>
  <gazebo reference="front_lidar_led">
    <visual>
      <material>
        <ambient>0 0 0 1</ambient>
        <diffuse>0 0 0 1</diffuse>
        <specular>0 0 0 0</specular>
        <emissive>0 1 0 1</emissive>
      </material>
    </visual>
  </gazebo>
  <link name="front_lidar_sensor"/>
  <joint name="front_lidar_device_joint" type="fixed">
    <parent link="front_lidar_box"/>
    <child link="front_lidar_sensor"/>
  </joint>
  <gazebo reference="front_lidar_sensor">
    <sensor name="laser_front" type="ray">
      <always_on>true</always_on>
      <pose> 0 0 0 0 0 0 </pose>
      <visualize>false</visualize>
      <update_rate>10</update_rate>
      <ray>
        <scan>
          <horizontal>
            <samples>180</samples>
            <min_angle>-1.5707963267948966</min_angle>
            <max_angle>1.5707963267948966</max_angle>
          </horizontal>
        </scan>
        <range>
          <min>0.3</min>
          <max>10</max>
          <resolution>0.5</resolution>
        </range>
      </ray>
      <plugin filename="libgazebo_ros_ray_sensor.so" name="laser_controller_front">
        <ros>
          <namespace>lidar</namespace>
          <remapping>~/out:=scan_front</remapping>
        </ros>
        <output_type>sensor_msgs/LaserScan</output_type>
        <frame_name>front_lidar</frame_name>
      </plugin>
    </sensor>
  </gazebo>
  <joint name="front_lidar_box_joint" type="fixed">
    <parent link="hood_top"/>
    <child link="front_lidar_box"/>
    <origin xyz="0.06108108108108107 0 0"/>
  </joint>
  <link name="back_lidar_box">
    <visual>
      <origin rpy="0 0.7853981633974483 0"/>
      <geometry>
        <box size="0.03 0.03 0.03"/>
      </geometry>
      <material name="GreyOne"/>
    </visual>
    <collision>
      <geometry>
        <box size="0.03 0.03 0.03"/>
      </geometry>
    </collision>
    <inertial>
      <origin xyz="0 0 0"/>
      <mass value="0.05"/>
      <inertia ixx="7.499999999999999e-06" ixy="0.0" ixz="0.0" iyy="7.499999999999999e-06" iyz="0.0" izz="7.499999999999999e-06"/>
    </inertial>
  </link>
  <link name="back_lidar_led">
    <visual>
      <origin xyz="0.0075 0 0.015"/>
      <geometry>
        <sphere radius="0.006"/>
      </geometry>
      <material name="RedOne"/>
    </visual>
    <collision>
      <geometry>
        <sphere radius="0.006"/>
      </geometry>
    </collision>
    <inertial>
      <origin/>
      <mass value="0.001"/>
      <inertia ixx="0.001" ixy="0.0" ixz="0.0" iyy="0.0" iyz="0.0" izz="0.0"/>
    </inertial>
  </link>
  <joint name="back_lidar_led_joint" type="fixed">
    <parent link="back_lidar_box"/>
    <child link="back_lidar_led"/>
  </joint>
  <gazebo reference="back_lidar_led">
    <visual>
      <material>
        <ambient>0 0 0 1</ambient>
        <diffuse>0 0 0 1</diffuse>
        <specular>0 0 0 0</specular>
        <emissive>0 1 0 1</emissive>
      </material>
    </visual>
  </gazebo>
  <link name="back_lidar_sensor"/>
  <joint name="back_lidar_device_joint" type="fixed">
    <parent link="back_lidar_box"/>
    <child link="back_lidar_sensor"/>
  </joint>
  <gazebo reference="back_lidar_sensor">
    <sensor name="laser_back" type="ray">
      <always_on>true</always_on>
      <pose> 0 0 0 0 0 0 </pose>
      <visualize>false</visualize>
      <update_rate>10</update_rate>
      <ray>
        <scan>
          <horizontal>
            <samples>180</samples>
            <min_angle>-1.5707963267948966</min_angle>
            <max_angle>1.5707963267948966</max_angle>
          </horizontal>
        </scan>
        <range>
          <min>0.3</min>
          <max>10</max>
          <resolution>0.5</resolution>
        </range>
      </ray>
      <plugin filename="libgazebo_ros_ray_sensor.so" name="laser_controller_back">
        <ros>
          <namespace>lidar</namespace>
          <remapping>~/out:=scan_back</remapping>
        </ros>
        <output_type>sensor_msgs/LaserScan</output_type>
        <frame_name>back_lidar</frame_name>
      </plugin>
    </sensor>
  </gazebo>
  <joint name="back_lidar_box_joint" type="fixed">
    <parent link="box_panel_back"/>
    <child link="back_lidar_box"/>
    <origin rpy="0 0 3.141592653589793" xyz="-0.015 0 0.15"/>
  </joint>
  <link name="front_optical_camera_box">
    <visual>
      <origin rpy="0 0.7853981633974483 0"/>
      <geometry>
        <box size="0.015 0.015 0.015"/>
      </geometry>
      <material name="GreyOne"/>
    </visual>
    <collision>
      <geometry>
        <box size="0.015 0.015 0.015"/>
      </geometry>
    </collision>
    <inertial>
      <origin/>
      <mass value="0.02"/>
      <inertia ixx="7.499999999999999e-07" ixy="0.0" ixz="0.0" iyy="7.499999999999999e-07" iyz="0.0" izz="7.499999999999999e-07"/>
    </inertial>
  </link>
  <link name="front_optical_camera_led">
    <visual>
      <origin xyz="0.00375 0 0.0075"/>
      <geometry>
        <sphere radius="0.00375"/>
      </geometry>
      <material name="RedOne"/>
    </visual>
  </link>
  <joint name="front_optical_camera_led_joint" type="fixed">
    <parent link="front_optical_camera_box"/>
    <child link="front_optical_camera_led"/>
  </joint>
  <gazebo reference="front_optical_camera_led">
    <visual>
      <material>
        <ambient>0 0 0 1</ambient>
        <diffuse>0 0 0 1</diffuse>
        <specular>0 0 0 0</specular>
        <emissive>0 1 0 1</emissive>
      </material>
    </visual>
  </gazebo>
  <link name="front_camera_optical"/>
  <gazebo reference="front_optical_camera_box">
    <sensor name="optical_camera_front" type="camera">
      <pose> 0 0 0 0 0 0 </pose>
      <visualize>true</visualize>
      <update_rate>0.5</update_rate>
      <camera>
        <horizontal_fov>1.2</horizontal_fov>
        <image>
          <format>R8G8B8</format>
          <width>640</width>
          <height>480</height>
        </image>
        <clip>
          <near>0.1</near>
          <far>8.5</far>
        </clip>
      </camera>
      <plugin filename="libgazebo_ros_camera.so" name="optical_camera_controller_front">
        <ros>
          <namespace>cameras</namespace>
        </ros>
        <frame_name>front_camera_optical</frame_name>
      </plugin>
    </sensor>
    <material>Gazebo/Grey</material>
  </gazebo>
  <joint name="front_optical_camera_box_joint" type="fixed">
    <parent link="box_panel_top"/>
    <child link="front_optical_camera_box"/>
    <origin xyz="0.13844594594594592 0.13333333333333333 0.015"/>
  </joint>
  <joint name="front_camera_optical_joint" type="fixed">
    <parent link="front_optical_camera_box"/>
    <child link="front_camera_optical"/>
    <origin rpy="-1.5707963267948966 0 -1.5707963267948966" xyz="0 0 0"/>
  </joint>
  <link name="back_optical_camera_box">
    <visual>
      <origin rpy="0 0.7853981633974483 0"/>
      <geometry>
        <box size="0.015 0.015 0.015"/>
      </geometry>
      <material name="GreyOne"/>
    </visual>
    <collision>
      <geometry>
        <box size="0.015 0.015 0.015"/>
      </geometry>
    </collision>
    <inertial>
      <origin/>
      <mass value="0.02"/>
      <inertia ixx="7.499999999999999e-07" ixy="0.0" ixz="0.0" iyy="7.499999999999999e-07" iyz="0.0" izz="7.499999999999999e-07"/>
    </inertial>
  </link>
  <link name="back_optical_camera_led">
    <visual>
      <origin xyz="0.00375 0 0.0075"/>
      <geometry>
        <sphere radius="0.00375"/>
      </geometry>
      <material name="RedOne"/>
    </visual>
  </link>
  <joint name="back_optical_camera_led_joint" type="fixed">
    <parent link="back_optical_camera_box"/>
    <child link="back_optical_camera_led"/>
  </joint>
  <gazebo reference="back_optical_camera_led">
    <visual>
      <material>
        <ambient>0 0 0 1</ambient>
        <diffuse>0 0 0 1</diffuse>
        <specular>0 0 0 0</specular>
        <emissive>0 1 0 1</emissive>
      </material>
    </visual>
  </gazebo>
  <link name="back_camera_optical"/>
  <gazebo reference="back_optical_camera_box">
    <sensor name="optical_camera_back" type="camera">
      <pose> 0 0 0 0 0 0 </pose>
      <visualize>true</visualize>
      <update_rate>0.5</update_rate>
      <camera>
        <horizontal_fov>1.2</horizontal_fov>
        <image>
          <format>R8G8B8</format>
          <width>640</width>
          <height>480</height>
        </image>
        <clip>
          <near>0.1</near>
          <far>8.5</far>
        </clip>
      </camera>
      <plugin filename="libgazebo_ros_camera.so" name="optical_camera_controller_back">
        <ros>
          <namespace>cameras</namespace>
        </ros>
        <frame_name>back_camera_optical</frame_name>
      </plugin>
    </sensor>
    <material>Gazebo/Grey</material>
  </gazebo>
  <joint name="back_camera_box_joint" type="fixed">
    <parent link="box_panel_back"/>
    <child link="back_optical_camera_box"/>
    <origin rpy="0 0 3.141592653589793" xyz="-0.015 0 0.2571428571428571"/>
  </joint>
  <joint name="back_camera_optical_joint" type="fixed">
    <parent link="back_optical_camera_box"/>
    <child link="back_camera_optical"/>
    <origin rpy="-1.5707963267948966 0 -1.5707963267948966" xyz="0 0 0"/>
  </joint>
  <link name="front_depth_camera_box">
    <visual>
      <origin rpy="0 0.7853981633974483 0"/>
      <geometry>
        <box size="0.015 0.015 0.015"/>
      </geometry>
      <material name="GreyOne"/>
    </visual>
    <collision>
      <geometry>
        <box size="0.015 0.015 0.015"/>
      </geometry>
    </collision>
    <inertial>
      <origin/>
      <mass value="0.02"/>
      <inertia ixx="7.499999999999999e-07" ixy="0.0" ixz="0.0" iyy="7.499999999999999e-07" iyz="0.0" izz="7.499999999999999e-07"/>
    </inertial>
  </link>
  <link name="front_depth_camera_led">
    <visual>
      <origin xyz="0.00375 0 0.0075"/>
      <geometry>
        <sphere radius="0.00375"/>
      </geometry>
      <material name="RedOne"/>
    </visual>
  </link>
  <joint name="front_depth_camera_led_joint" type="fixed">
    <parent link="front_depth_camera_box"/>
    <child link="front_depth_camera_led"/>
  </joint>
  <gazebo reference="front_depth_camera_led">
    <visual>
      <material>
        <ambient>0 0 0 1</ambient>
        <diffuse>0 0 0 1</diffuse>
        <specular>0 0 0 0</specular>
        <emissive>0 1 0 1</emissive>
      </material>
    </visual>
  </gazebo>
  <link name="front_camera_depth"/>
  <gazebo reference="front_depth_camera_box">
    <sensor name="depth_camera_front" type="depth">
      <pose> 0 0 0 0 0 0 </pose>
      <visualize>true</visualize>
      <update_rate>20</update_rate>
      <camera>
        <horizontal_fov>1.8</horizontal_fov>
        <image>
          <format>B8G8R8</format>
          <width>640</width>
          <height>480</height>
        </image>
        <clip>
          <near>0.1</near>
          <far>8.0</far>
        </clip>
      </camera>
      <plugin filename="libgazebo_ros_camera.so" name="depth_camera_controller_front">
        <ros>
          <namespace>cameras</namespace>
        </ros>
        <frame_name>front_camera_depth</frame_name>
        <hack_baseline>1</hack_baseline>
        <min_depth>2</min_depth>
        <max_depth>90</max_depth>
      </plugin>
    </sensor>
    <material>Gazebo/Grey</material>
  </gazebo>
  <joint name="front_depth_camera_box_joint" type="fixed">
    <parent link="box_panel_top"/>
    <child link="front_depth_camera_box"/>
    <origin xyz="0.13844594594594592 -0.13333333333333333 0.015"/>
  </joint>
  <joint name="front_camera_depth_joint" type="fixed">
    <parent link="front_depth_camera_box"/>
    <child link="front_camera_depth"/>
    <origin rpy="-1.5707963267948966 0 -1.5707963267948966" xyz="0 0 0"/>
  </joint>
  <gazebo>
    <plugin filename="libgazebo_ros_diff_drive.so" name="differential_drive_controller">
      <num_wheel_pairs>2</num_wheel_pairs>
      <left_joint>front_left_wheel_joint</left_joint>
      <right_joint>front_right_wheel_joint</right_joint>
      <left_joint>back_left_wheel_joint</left_joint>
      <right_joint>back_right_wheel_joint</right_joint>
      <wheel_diameter>0.1846153846153846</wheel_diameter>
      <wheel_separation>0.485</wheel_separation>
      <DEBUG axle_="0.51" diam_="0.1846153846153846" sep_="0.485"/>
      <max_wheel_torque>30</max_wheel_torque>
      <max_wheel_acceleration>5.0</max_wheel_acceleration>
      <robot_base_frame>base_link</robot_base_frame>
      <odometry_frame>odom</odometry_frame>
      <publish_odom>true</publish_odom>
      <publish_odom_tf>true</publish_odom_tf>
      <publish_wheel_tf>true</publish_wheel_tf>
      <ros>
        <remapping>cmd_vel:=/differential_drive_controller/cmd_vel_unstamped</remapping>
      </ros>
    </plugin>
  </gazebo>
  <link name="articulation_base_left">
    <visual>
      <origin rpy="1.5707963267948966 0 0" xyz="0 0 0"/>
      <geometry>
        <cylinder length="0.007" radius="0.016530612244897956"/>
      </geometry>
      <material name="PurpleOne"/>
    </visual>
    <collision>
      <origin rpy="1.5707963267948966 0 0" xyz="0 0 0"/>
      <geometry>
        <cylinder length="0.007" radius="0.016530612244897956"/>
      </geometry>
    </collision>
    <inertial>
      <origin rpy="1.5707963267948966 0 0" xyz="0 0 0"/>
      <mass value="0.33333333333333337"/>
      <inertia ixx="2.413287287704197e-05" ixy="0.0" ixz="0.0" iyy="2.413287287704197e-05" iyz="0.0" izz="4.5543523531861716e-05"/>
    </inertial>
  </link>
  <gazebo reference="articulation_base_left">
    <visual>
      <material>
        <ambient>0.589 0.793 1.0 1.0</ambient>
        <diffuse>0.56666695 0.56666695 0.56666695 1.0</diffuse>
        <specular>0.6000003 0.6000003 0.6000003 1.0</specular>
      </material>
    </visual>
  </gazebo>
  <link name="manipulator_1st_left">
    <visual>
      <origin rpy="1.5707963267948966 0 0" xyz="0 0 0"/>
      <geometry>
        <cylinder length="0.03" radius="0.012397959183673469"/>
      </geometry>
      <material name="BlueOne"/>
    </visual>
    <collision>
      <origin rpy="1.5707963267948966 0 0" xyz="0 0 0"/>
      <geometry>
        <cylinder length="0.03" radius="0.012397959183673469"/>
      </geometry>
    </collision>
    <DEBUG length_="0.03" mass_="0.01449"/>
    <inertial>
      <origin/>
      <mass value="0.014486768893311927"/>
      <inertia ixx="0.002" ixy="0.0" ixz="0.0" iyy="0.0" iyz="0.0" izz="0.0"/>
    </inertial>
  </link>
  <gazebo reference="manipulator_1st_left">
    <visual>
      <material>
        <ambient>0.5 0.5 0.5 1.0</ambient>
        <diffuse>0.56666695 0.56666695 0.56666695 1.0</diffuse>
        <specular>0.6000003 0.6000003 0.6000003 1.0</specular>
      </material>
    </visual>
  </gazebo>
  <link name="articulation_1st_left">
    <visual>
      <origin rpy="0 0 0" xyz="0 0 0"/>
      <geometry>
        <cylinder length="0.05579081632653061" radius="0.013775510204081631"/>
      </geometry>
      <material name="PurpleOne"/>
    </visual>
    <collision>
      <origin rpy="0 0 0" xyz="0 0 0"/>
      <geometry>
        <cylinder length="0.05579081632653061" radius="0.013775510204081631"/>
      </geometry>
    </collision>
    <inertial>
      <origin rpy="0 0 0" xyz="0 0 0"/>
      <mass value="0.16666666666666669"/>
      <inertia ixx="5.113762820179092e-05" ixy="0.0" ixz="0.0" iyy="5.113762820179092e-05" iyz="0.0" izz="1.5813723448563096e-05"/>
    </inertial>
  </link>
  <gazebo reference="articulation_1st_left">
    <visual>
      <material>
        <ambient>0.589 0.793 1.0 1.0</ambient>
        <diffuse>0.56666695 0.56666695 0.56666695 1.0</diffuse>
        <specular>0.6000003 0.6000003 0.6000003 1.0</specular>
      </material>
    </visual>
  </gazebo>
  <link name="manipulator_2nd_left">
    <visual>
      <origin rpy="0 1.5707963267948966 0" xyz="0 0 0"/>
      <geometry>
        <cylinder length="0.19999999999999998" radius="0.012397959183673469"/>
      </geometry>
      <material name="BlueOne"/>
    </visual>
    <collision>
      <origin rpy="0 1.5707963267948966 0" xyz="0 0 0"/>
      <geometry>
        <cylinder length="0.19999999999999998" radius="0.012397959183673469"/>
      </geometry>
    </collision>
    <DEBUG length_="0.19999999999999998" mass_="0.09658"/>
    <inertial>
      <origin/>
      <mass value="0.09657845928874617"/>
      <inertia ixx="0.002" ixy="0.0" ixz="0.0" iyy="0.0" iyz="0.0" izz="0.0"/>
    </inertial>
  </link>
  <gazebo reference="manipulator_2nd_left">
    <visual>
      <material>
        <ambient>0.5 0.5 0.5 1.0</ambient>
        <diffuse>0.56666695 0.56666695 0.56666695 1.0</diffuse>
        <specular>0.6000003 0.6000003 0.6000003 1.0</specular>
      </material>
    </visual>
  </gazebo>
  <link name="articulation_2nd_left">
    <visual>
      <origin rpy="0 0 0" xyz="0 0 0"/>
      <geometry>
        <cylinder length="0.05579081632653061" radius="0.013775510204081631"/>
      </geometry>
      <material name="PurpleOne"/>
    </visual>
    <collision>
      <origin rpy="0 0 0" xyz="0 0 0"/>
      <geometry>
        <cylinder length="0.05579081632653061" radius="0.013775510204081631"/>
      </geometry>
    </collision>
    <inertial>
      <origin rpy="0 0 0" xyz="0 0 0"/>
      <mass value="0.16666666666666669"/>
      <inertia ixx="5.113762820179092e-05" ixy="0.0" ixz="0.0" iyy="5.113762820179092e-05" iyz="0.0" izz="1.5813723448563096e-05"/>
    </inertial>
  </link>
  <gazebo reference="articulation_2nd_left">
    <visual>
      <material>
        <ambient>0.589 0.793 1.0 1.0</ambient>
        <diffuse>0.56666695 0.56666695 0.56666695 1.0</diffuse>
        <specular>0.6000003 0.6000003 0.6000003 1.0</specular>
      </material>
    </visual>
  </gazebo>
  <link name="manipulator_3rd_left">
    <visual>
      <origin rpy="0 1.5707963267948966 0" xyz="0 0 0"/>
      <geometry>
        <cylinder length="0.2" radius="0.012397959183673469"/>
      </geometry>
      <material name="BlueOne"/>
    </visual>
    <collision>
      <origin rpy="0 1.5707963267948966 0" xyz="0 0 0"/>
      <geometry>
        <cylinder length="0.2" radius="0.012397959183673469"/>
      </geometry>
    </collision>
    <DEBUG length_="0.2" mass_="0.09658"/>
    <inertial>
      <origin/>
      <mass value="0.09657845928874619"/>
      <inertia ixx="0.002" ixy="0.0" ixz="0.0" iyy="0.0" iyz="0.0" izz="0.0"/>
    </inertial>
  </link>
  <gazebo reference="manipulator_3rd_left">
    <visual>
      <material>
        <ambient>0.5 0.5 0.5 1.0</ambient>
        <diffuse>0.56666695 0.56666695 0.56666695 1.0</diffuse>
        <specular>0.6000003 0.6000003 0.6000003 1.0</specular>
      </material>
    </visual>
  </gazebo>
  <link name="articulation_end_effector_left">
    <visual>
      <origin rpy="0 0 0" xyz="0 0 0"/>
      <geometry>
        <sphere radius="0.014"/>
      </geometry>
      <material name="WhiteOne"/>
    </visual>
    <collision>
      <origin rpy="0 0 0" xyz="0 0 0"/>
      <geometry>
        <sphere radius="0.014"/>
      </geometry>
    </collision>
    <inertial>
      <origin xyz="0 0 0"/>
      <mass value="0.16666666666666669"/>
      <inertia ixx="1.306666666666667e-05" ixy="0.0" ixz="0.0" iyy="1.306666666666667e-05" iyz="0.0" izz="1.306666666666667e-05"/>
    </inertial>
  </link>
  <gazebo reference="articulation_end_effector_left">
    <visual>
      <material>
        <ambient>0.589 0.793 1.0 1.0</ambient>
        <diffuse>0.56666695 0.56666695 0.56666695 1.0</diffuse>
        <specular>0.6000003 0.6000003 0.6000003 1.0</specular>
      </material>
    </visual>
  </gazebo>
  <link name="left_up_gripper">
    <visual>
      <origin rpy="-0.15707963267948963 0 0" xyz="0 0 0"/>
      <geometry>
        <mesh filename="file:///home/osin/dev_ws/install/robot_frame/share/robot_frame/description/resources/gripper/l_finger_.dae" scale="0.5 0.5 0.5"/>
      </geometry>
    </visual>
    <collision>
      <geometry>
        <mesh filename="file:///home/osin/dev_ws/install/robot_frame/share/robot_frame/description/resources/gripper/l_finger_.dae" scale="0.5 0.5 0.5"/>
      </geometry>
      <origin rpy="-0.15707963267948963 0 0" xyz="0 0 0"/>
    </collision>
    <inertial>
      <mass value="0.001"/>
      <inertia ixx="1.0" ixy="0.0" ixz="0.0" iyy="1.0" iyz="0.0" izz="1.0"/>
    </inertial>
  </link>
  <link name="left_up_gripper_tip">
    <visual>
      <origin rpy="-0.15707963267948963 0 0" xyz="0.046 0.0039 0"/>
      <geometry>
        <mesh filename="file:///home/osin/dev_ws/install/robot_frame/share/robot_frame/description/resources/gripper/l_finger_tip.dae" scale="0.5 0.5 0.5"/>
      </geometry>
    </visual>
    <collision>
      <geometry>
        <mesh filename="file:///home/osin/dev_ws/install/robot_frame/share/robot_frame/description/resources/gripper/l_finger_tip.dae" scale="0.5 0.5 0.5"/>
      </geometry>
      <origin rpy="-0.15707963267948963 0 0" xyz="0.046 0.0039 0"/>
    </collision>
    <inertial>
      <mass value="0.0003333333333333333"/>
      <inertia ixx="1.0" ixy="0.0" ixz="0.0" iyy="1.0" iyz="0.0" izz="1.0"/>
    </inertial>
  </link>
  <link name="left_down_gripper">
    <visual>
      <origin rpy="-3.2986722862692828 0 0" xyz="0 0 0"/>
      <geometry>
        <mesh filename="file:///home/osin/dev_ws/install/robot_frame/share/robot_frame/description/resources/gripper/l_finger_.dae" scale="0.5 0.5 0.5"/>
      </geometry>
    </visual>
    <collision>
      <geometry>
        <mesh filename="file:///home/osin/dev_ws/install/robot_frame/share/robot_frame/description/resources/gripper/l_finger_.dae" scale="0.5 0.5 0.5"/>
      </geometry>
      <origin rpy="-3.2986722862692828 0 0" xyz="0 0 0"/>
    </collision>
    <inertial>
      <mass value="0.001"/>
      <inertia ixx="1.0" ixy="0.0" ixz="0.0" iyy="1.0" iyz="0.0" izz="1.0"/>
    </inertial>
  </link>
  <link name="left_down_gripper_tip">
    <visual>
      <origin rpy="-3.2986722862692828 0 0" xyz="0.046 0.0039 0"/>
      <geometry>
        <mesh filename="file:///home/osin/dev_ws/install/robot_frame/share/robot_frame/description/resources/gripper/l_finger_tip.dae" scale="0.5 0.5 0.5"/>
      </geometry>
    </visual>
    <collision>
      <geometry>
        <mesh filename="file:///home/osin/dev_ws/install/robot_frame/share/robot_frame/description/resources/gripper/l_finger_tip.dae" scale="0.5 0.5 0.5"/>
      </geometry>
      <origin rpy="-3.2986722862692828 0 0" xyz="0.046 0.0039 0"/>
    </collision>
    <inertial>
      <mass value="0.0003333333333333333"/>
      <inertia ixx="1.0" ixy="0.0" ixz="0.0" iyy="1.0" iyz="0.0" izz="1.0"/>
    </inertial>
  </link>
  <link name="articulation_base_right">
    <visual>
      <origin rpy="1.5707963267948966 0 0" xyz="0 0 0"/>
      <geometry>
        <cylinder length="0.007" radius="0.016530612244897956"/>
      </geometry>
      <material name="PurpleOne"/>
    </visual>
    <collision>
      <origin rpy="1.5707963267948966 0 0" xyz="0 0 0"/>
      <geometry>
        <cylinder length="0.007" radius="0.016530612244897956"/>
      </geometry>
    </collision>
    <inertial>
      <origin rpy="1.5707963267948966 0 0" xyz="0 0 0"/>
      <mass value="0.33333333333333337"/>
      <inertia ixx="2.413287287704197e-05" ixy="0.0" ixz="0.0" iyy="2.413287287704197e-05" iyz="0.0" izz="4.5543523531861716e-05"/>
    </inertial>
  </link>
  <gazebo reference="articulation_base_right">
    <visual>
      <material>
        <ambient>0.589 0.793 1.0 1.0</ambient>
        <diffuse>0.56666695 0.56666695 0.56666695 1.0</diffuse>
        <specular>0.6000003 0.6000003 0.6000003 1.0</specular>
      </material>
    </visual>
  </gazebo>
  <link name="manipulator_1st_right">
    <visual>
      <origin rpy="-1.5707963267948966 0 0" xyz="0 0 0"/>
      <geometry>
        <cylinder length="0.03" radius="0.012397959183673469"/>
      </geometry>
      <material name="BlueOne"/>
    </visual>
    <collision>
      <origin rpy="-1.5707963267948966 0 0" xyz="0 0 0"/>
      <geometry>
        <cylinder length="0.03" radius="0.012397959183673469"/>
      </geometry>
    </collision>
    <DEBUG length_="0.03" mass_="0.01449"/>
    <inertial>
      <origin/>
      <mass value="0.014486768893311927"/>
      <inertia ixx="0.002" ixy="0.0" ixz="0.0" iyy="0.0" iyz="0.0" izz="0.0"/>
    </inertial>
  </link>
  <gazebo reference="manipulator_1st_right">
    <visual>
      <material>
        <ambient>0.5 0.5 0.5 1.0</ambient>
        <diffuse>0.56666695 0.56666695 0.56666695 1.0</diffuse>
        <specular>0.6000003 0.6000003 0.6000003 1.0</specular>
      </material>
    </visual>
  </gazebo>
  <link name="articulation_1st_right">
    <visual>
      <origin rpy="0 0 0" xyz="0 0 0"/>
      <geometry>
        <cylinder length="0.05579081632653061" radius="0.013775510204081631"/>
      </geometry>
      <material name="PurpleOne"/>
    </visual>
    <collision>
      <origin rpy="0 0 0" xyz="0 0 0"/>
      <geometry>
        <cylinder length="0.05579081632653061" radius="0.013775510204081631"/>
      </geometry>
    </collision>
    <inertial>
      <origin rpy="0 0 0" xyz="0 0 0"/>
      <mass value="0.16666666666666669"/>
      <inertia ixx="5.113762820179092e-05" ixy="0.0" ixz="0.0" iyy="5.113762820179092e-05" iyz="0.0" izz="1.5813723448563096e-05"/>
    </inertial>
  </link>
  <gazebo reference="articulation_1st_right">
    <visual>
      <material>
        <ambient>0.589 0.793 1.0 1.0</ambient>
        <diffuse>0.56666695 0.56666695 0.56666695 1.0</diffuse>
        <specular>0.6000003 0.6000003 0.6000003 1.0</specular>
      </material>
    </visual>
  </gazebo>
  <link name="manipulator_2nd_right">
    <visual>
      <origin rpy="0 1.5707963267948966 0" xyz="0 0 0"/>
      <geometry>
        <cylinder length="0.19999999999999998" radius="0.012397959183673469"/>
      </geometry>
      <material name="BlueOne"/>
    </visual>
    <collision>
      <origin rpy="0 1.5707963267948966 0" xyz="0 0 0"/>
      <geometry>
        <cylinder length="0.19999999999999998" radius="0.012397959183673469"/>
      </geometry>
    </collision>
    <DEBUG length_="0.19999999999999998" mass_="0.09658"/>
    <inertial>
      <origin/>
      <mass value="0.09657845928874617"/>
      <inertia ixx="0.002" ixy="0.0" ixz="0.0" iyy="0.0" iyz="0.0" izz="0.0"/>
    </inertial>
  </link>
  <gazebo reference="manipulator_2nd_right">
    <visual>
      <material>
        <ambient>0.5 0.5 0.5 1.0</ambient>
        <diffuse>0.56666695 0.56666695 0.56666695 1.0</diffuse>
        <specular>0.6000003 0.6000003 0.6000003 1.0</specular>
      </material>
    </visual>
  </gazebo>
  <link name="articulation_2nd_right">
    <visual>
      <origin rpy="0 0 0" xyz="0 0 0"/>
      <geometry>
        <cylinder length="0.05579081632653061" radius="0.013775510204081631"/>
      </geometry>
      <material name="PurpleOne"/>
    </visual>
    <collision>
      <origin rpy="0 0 0" xyz="0 0 0"/>
      <geometry>
        <cylinder length="0.05579081632653061" radius="0.013775510204081631"/>
      </geometry>
    </collision>
    <inertial>
      <origin rpy="0 0 0" xyz="0 0 0"/>
      <mass value="0.16666666666666669"/>
      <inertia ixx="5.113762820179092e-05" ixy="0.0" ixz="0.0" iyy="5.113762820179092e-05" iyz="0.0" izz="1.5813723448563096e-05"/>
    </inertial>
  </link>
  <gazebo reference="articulation_2nd_right">
    <visual>
      <material>
        <ambient>0.589 0.793 1.0 1.0</ambient>
        <diffuse>0.56666695 0.56666695 0.56666695 1.0</diffuse>
        <specular>0.6000003 0.6000003 0.6000003 1.0</specular>
      </material>
    </visual>
  </gazebo>
  <link name="manipulator_3rd_right">
    <visual>
      <origin rpy="0 1.5707963267948966 0" xyz="0 0 0"/>
      <geometry>
        <cylinder length="0.2" radius="0.012397959183673469"/>
      </geometry>
      <material name="BlueOne"/>
    </visual>
    <collision>
      <origin rpy="0 1.5707963267948966 0" xyz="0 0 0"/>
      <geometry>
        <cylinder length="0.2" radius="0.012397959183673469"/>
      </geometry>
    </collision>
    <DEBUG length_="0.2" mass_="0.09658"/>
    <inertial>
      <origin/>
      <mass value="0.09657845928874619"/>
      <inertia ixx="0.002" ixy="0.0" ixz="0.0" iyy="0.0" iyz="0.0" izz="0.0"/>
    </inertial>
  </link>
  <gazebo reference="manipulator_3rd_right">
    <visual>
      <material>
        <ambient>0.5 0.5 0.5 1.0</ambient>
        <diffuse>0.56666695 0.56666695 0.56666695 1.0</diffuse>
        <specular>0.6000003 0.6000003 0.6000003 1.0</specular>
      </material>
    </visual>
  </gazebo>
  <link name="articulation_end_effector_right">
    <visual>
      <origin rpy="0 0 0" xyz="0 0 0"/>
      <geometry>
        <sphere radius="0.014"/>
      </geometry>
      <material name="WhiteOne"/>
    </visual>
    <collision>
      <origin rpy="0 0 0" xyz="0 0 0"/>
      <geometry>
        <sphere radius="0.014"/>
      </geometry>
    </collision>
    <inertial>
      <origin xyz="0 0 0"/>
      <mass value="0.16666666666666669"/>
      <inertia ixx="1.306666666666667e-05" ixy="0.0" ixz="0.0" iyy="1.306666666666667e-05" iyz="0.0" izz="1.306666666666667e-05"/>
    </inertial>
  </link>
  <gazebo reference="articulation_end_effector_right">
    <visual>
      <material>
        <ambient>0.589 0.793 1.0 1.0</ambient>
        <diffuse>0.56666695 0.56666695 0.56666695 1.0</diffuse>
        <specular>0.6000003 0.6000003 0.6000003 1.0</specular>
      </material>
    </visual>
  </gazebo>
  <link name="right_up_gripper">
    <visual>
      <origin rpy="0.1570796326794898 0 0" xyz="0 0 0"/>
      <geometry>
        <mesh filename="file:///home/osin/dev_ws/install/robot_frame/share/robot_frame/description/resources/gripper/l_finger_.dae" scale="0.5 0.5 0.5"/>
      </geometry>
    </visual>
    <collision>
      <geometry>
        <mesh filename="file:///home/osin/dev_ws/install/robot_frame/share/robot_frame/description/resources/gripper/l_finger_.dae" scale="0.5 0.5 0.5"/>
      </geometry>
      <origin rpy="0.1570796326794898 0 0" xyz="0 0 0"/>
    </collision>
    <inertial>
      <mass value="0.001"/>
      <inertia ixx="1.0" ixy="0.0" ixz="0.0" iyy="1.0" iyz="0.0" izz="1.0"/>
    </inertial>
  </link>
  <link name="right_up_gripper_tip">
    <visual>
      <origin rpy="0.1570796326794898 0 0" xyz="0.046 0.0039 0"/>
      <geometry>
        <mesh filename="file:///home/osin/dev_ws/install/robot_frame/share/robot_frame/description/resources/gripper/l_finger_tip.dae" scale="0.5 0.5 0.5"/>
      </geometry>
    </visual>
    <collision>
      <geometry>
        <mesh filename="file:///home/osin/dev_ws/install/robot_frame/share/robot_frame/description/resources/gripper/l_finger_tip.dae" scale="0.5 0.5 0.5"/>
      </geometry>
      <origin rpy="0.1570796326794898 0 0" xyz="0.046 0.0039 0"/>
    </collision>
    <inertial>
      <mass value="0.0003333333333333333"/>
      <inertia ixx="1.0" ixy="0.0" ixz="0.0" iyy="1.0" iyz="0.0" izz="1.0"/>
    </inertial>
  </link>
  <link name="right_down_gripper">
    <visual>
      <origin rpy="-2.9845130209103035 0 0" xyz="0 0 0"/>
      <geometry>
        <mesh filename="file:///home/osin/dev_ws/install/robot_frame/share/robot_frame/description/resources/gripper/l_finger_.dae" scale="0.5 0.5 0.5"/>
      </geometry>
    </visual>
    <collision>
      <geometry>
        <mesh filename="file:///home/osin/dev_ws/install/robot_frame/share/robot_frame/description/resources/gripper/l_finger_.dae" scale="0.5 0.5 0.5"/>
      </geometry>
      <origin rpy="-2.9845130209103035 0 0" xyz="0 0 0"/>
    </collision>
    <inertial>
      <mass value="0.001"/>
      <inertia ixx="1.0" ixy="0.0" ixz="0.0" iyy="1.0" iyz="0.0" izz="1.0"/>
    </inertial>
  </link>
  <link name="right_down_gripper_tip">
    <visual>
      <origin rpy="-2.9845130209103035 0 0" xyz="0.046 0.0039 0"/>
      <geometry>
        <mesh filename="file:///home/osin/dev_ws/install/robot_frame/share/robot_frame/description/resources/gripper/l_finger_tip.dae" scale="0.5 0.5 0.5"/>
      </geometry>
    </visual>
    <collision>
      <geometry>
        <mesh filename="file:///home/osin/dev_ws/install/robot_frame/share/robot_frame/description/resources/gripper/l_finger_tip.dae" scale="0.5 0.5 0.5"/>
      </geometry>
      <origin rpy="-2.9845130209103035 0 0" xyz="0.046 0.0039 0"/>
    </collision>
    <inertial>
      <mass value="0.0003333333333333333"/>
      <inertia ixx="1.0" ixy="0.0" ixz="0.0" iyy="1.0" iyz="0.0" izz="1.0"/>
    </inertial>
  </link>
  <joint name="left_abase_gholder_joint" type="fixed">
    <parent link="box_gripper_holder_left"/>
    <child link="articulation_base_left"/>
    <origin xyz="0 0.0075 0"/>
  </joint>
  <joint name="left_m1st_abase_joint" type="revolute">
    <vc_robot_controller side="left" type="manipulators"/>
    <parent link="articulation_base_left"/>
    <child link="manipulator_1st_left"/>
    <axis xyz="0 1 0"/>
    <dynamics damping="5"/>
    <origin rpy="0 0 0" xyz="0 0.015 0"/>
    <limit effort="100.0" lower="-2.99" upper="0.1" velocity="1"/>
  </joint>
  <joint name="left_a1st_m1st_joint" type="revolute">
    <vc_robot_controller side="left" type="manipulators"/>
    <parent link="manipulator_1st_left"/>
    <child link="articulation_1st_left"/>
    <origin rpy="0 0 0" xyz="0 0.021887755102040815 -0.012397959183673469"/>
    <axis xyz="0 0 1.0"/>
    <limit effort="100.0" lower=".0" upper="1.5" velocity="1"/>
    <dynamics damping="5"/>
  </joint>
  <joint name="left_m2nd_a1st_joint" type="fixed">
    <parent link="articulation_1st_left"/>
    <child link="manipulator_2nd_left"/>
    <origin xyz="0.09999999999999999 0 -0.011158163265306121"/>
  </joint>
  <joint name="left_a2nd_m2nd_joint" type="revolute">
    <vc_robot_controller side="left" type="manipulators"/>
    <parent link="manipulator_2nd_left"/>
    <child link="articulation_2nd_left"/>
    <origin xyz="0.09999999999999999 0 -0.011158163265306121"/>
    <axis xyz="0 0 1.0"/>
    <limit effort="100.0" lower="-1.5" upper="1.5" velocity="1"/>
    <dynamics damping="5"/>
  </joint>
  <joint name="left_m3rd_a2nd_joint" type="fixed">
    <parent link="articulation_2nd_left"/>
    <child link="manipulator_3rd_left"/>
    <origin xyz="0.1 0 -0.011158163265306121"/>
  </joint>
  <joint name="left_ard_m3rd_joint" type="fixed">
    <parent link="manipulator_3rd_left"/>
    <child link="articulation_end_effector_left"/>
    <origin xyz="0.1 0 0"/>
  </joint>
  <transmission name="trans_left_m1st_abase">
    <type>transmission_interface/SimpleTransmission</type>
    <joint name="left_m1st_abase_joint" role="left_m1st_abase_joint">
      <hardwareInterface>hardware_interface/PositionJointInterface</hardwareInterface>
    </joint>
    <actuator name="actuator_left_m1st_abase" role="actuator_left_m1st_abase">
      <mechanicalReduction>1</mechanicalReduction>
      <hardwareInterface>hardware_interface/PositionJointInterface</hardwareInterface>
    </actuator>
  </transmission>
  <transmission name="trans_left_a1st_m1st">
    <type>transmission_interface/SimpleTransmission</type>
    <joint name="left_a1st_m1st_joint" role="left_a1st_m1st_joint">
      <hardwareInterface>hardware_interface/PositionJointInterface</hardwareInterface>
    </joint>
    <actuator name="actuator_left_a1st_m1st" role="actuator_left_a1st_m1st">
      <mechanicalReduction>1</mechanicalReduction>
      <hardwareInterface>hardware_interface/PositionJointInterface</hardwareInterface>
    </actuator>
  </transmission>
  <transmission name="trans_left_a2nd_m2nd">
    <type>transmission_interface/SimpleTransmission</type>
    <joint name="left_a2nd_m2nd_joint" role="left_a2nd_m2nd_joint">
      <hardwareInterface>hardware_interface/PositionJointInterface</hardwareInterface>
    </joint>
    <actuator name="actuator_left_a2nd_m2nd" role="actuator_left_a2nd_m2nd">
      <mechanicalReduction>1</mechanicalReduction>
      <hardwareInterface>hardware_interface/PositionJointInterface</hardwareInterface>
    </actuator>
  </transmission>
  <link name="left_gripper_base">
    <inertial>
      <mass value="2e-06"/>
      <inertia ixx="1.1e-09" ixy="0" ixz="0" iyy="1.1e-09" iyz="0" izz="1.1e-09"/>
    </inertial>
  </link>
  <joint name="left_gripper_to_flange" type="fixed">
    <parent link="articulation_end_effector_left"/>
    <child link="left_gripper_base"/>
  </joint>
  <joint name="left_gripper_controller" type="revolute">
    <vc_robot_controller side="left" type="grippers"/>
    <vc_robot_controller side="left" type="gripper_action"/>
    <axis xyz="0 0 1"/>
    <limit effort="1000.0" lower="0.0" upper="0.548" velocity="0.5"/>
    <origin rpy="0 0 0" xyz="0.007 0.01 0"/>
    <parent link="left_gripper_base"/>
    <child link="left_up_gripper"/>
    <dynamics damping="5"/>
  </joint>
  <joint name="left_up_gripper_tip_joint" type="fixed">
    <parent link="left_up_gripper"/>
    <child link="left_up_gripper_tip"/>
    <dynamics damping="5"/>
  </joint>
  <joint name="left_down_gripper_joint" type="revolute">
    <vc_robot_controller side="left" type="gripper_mimic"/>
    <axis xyz="0 0 -1"/>
    <limit effort="1000.0" lower="0.0" upper="0.548" velocity="0.5"/>
    <origin rpy="0 0 0" xyz="0.007 -0.01 0"/>
    <parent link="left_gripper_base"/>
    <child link="left_down_gripper"/>
    <dynamics damping="5"/>
    <mimic joint="left_gripper_controller" multiplier="1.0" offset="0"/>
  </joint>
  <joint name="left_down_gripper_tip_joint" type="fixed">
    <parent link="left_down_gripper"/>
    <child link="left_down_gripper_tip"/>
    <dynamics damping="5"/>
  </joint>
  <transmission name="trans_left_gripper_controller">
    <type>transmission_interface/SimpleTransmission</type>
    <joint name="left_gripper_controller_joint" role="left_gripper_controller_joint">
      <hardwareInterface>hardware_interface/PositionJointInterface</hardwareInterface>
    </joint>
    <actuator name="actuator_left_gripper_controller" role="actuator_left_gripper_controller">
      <mechanicalReduction>1</mechanicalReduction>
      <hardwareInterface>hardware_interface/PositionJointInterface</hardwareInterface>
    </actuator>
  </transmission>
  <joint name="right_abase_gholder_joint" type="fixed">
    <parent link="box_gripper_holder_right"/>
    <child link="articulation_base_right"/>
    <origin xyz="0 -0.0075 0"/>
  </joint>
  <joint name="right_m1st_abase_joint" type="revolute">
    <vc_robot_controller side="right" type="manipulators"/>
    <parent link="articulation_base_right"/>
    <child link="manipulator_1st_right"/>
    <axis xyz="0 1 0"/>
    <dynamics damping="5"/>
    <origin rpy="0 0 0" xyz="0 -0.015 0"/>
    <limit effort="100.0" lower="-2.99" upper="0.1" velocity="1"/>
  </joint>
  <joint name="right_a1st_m1st_joint" type="revolute">
    <vc_robot_controller side="right" type="manipulators"/>
    <parent link="manipulator_1st_right"/>
    <child link="articulation_1st_right"/>
    <origin rpy="0 0 0" xyz="0 -0.021887755102040815 -0.012397959183673469"/>
    <axis xyz="0 0 -1.0"/>
    <limit effort="100.0" lower=".0" upper="1.5" velocity="1"/>
    <dynamics damping="5"/>
  </joint>
  <joint name="right_m2nd_a1st_joint" type="fixed">
    <parent link="articulation_1st_right"/>
    <child link="manipulator_2nd_right"/>
    <origin xyz="0.09999999999999999 0 -0.011158163265306121"/>
  </joint>
  <joint name="right_a2nd_m2nd_joint" type="revolute">
    <vc_robot_controller side="right" type="manipulators"/>
    <parent link="manipulator_2nd_right"/>
    <child link="articulation_2nd_right"/>
    <origin xyz="0.09999999999999999 0 -0.011158163265306121"/>
    <axis xyz="0 0 -1.0"/>
    <limit effort="100.0" lower="-1.5" upper="1.5" velocity="1"/>
    <dynamics damping="5"/>
  </joint>
  <joint name="right_m3rd_a2nd_joint" type="fixed">
    <parent link="articulation_2nd_right"/>
    <child link="manipulator_3rd_right"/>
    <origin xyz="0.1 0 -0.011158163265306121"/>
  </joint>
  <joint name="right_ard_m3rd_joint" type="fixed">
    <parent link="manipulator_3rd_right"/>
    <child link="articulation_end_effector_right"/>
    <origin xyz="0.1 0 0"/>
  </joint>
  <transmission name="trans_right_m1st_abase">
    <type>transmission_interface/SimpleTransmission</type>
    <joint name="right_m1st_abase_joint" role="right_m1st_abase_joint">
      <hardwareInterface>hardware_interface/PositionJointInterface</hardwareInterface>
    </joint>
    <actuator name="actuator_right_m1st_abase" role="actuator_right_m1st_abase">
      <mechanicalReduction>1</mechanicalReduction>
      <hardwareInterface>hardware_interface/PositionJointInterface</hardwareInterface>
    </actuator>
  </transmission>
  <transmission name="trans_right_a1st_m1st">
    <type>transmission_interface/SimpleTransmission</type>
    <joint name="right_a1st_m1st_joint" role="right_a1st_m1st_joint">
      <hardwareInterface>hardware_interface/PositionJointInterface</hardwareInterface>
    </joint>
    <actuator name="actuator_right_a1st_m1st" role="actuator_right_a1st_m1st">
      <mechanicalReduction>1</mechanicalReduction>
      <hardwareInterface>hardware_interface/PositionJointInterface</hardwareInterface>
    </actuator>
  </transmission>
  <transmission name="trans_right_a2nd_m2nd">
    <type>transmission_interface/SimpleTransmission</type>
    <joint name="right_a2nd_m2nd_joint" role="right_a2nd_m2nd_joint">
      <hardwareInterface>hardware_interface/PositionJointInterface</hardwareInterface>
    </joint>
    <actuator name="actuator_right_a2nd_m2nd" role="actuator_right_a2nd_m2nd">
      <mechanicalReduction>1</mechanicalReduction>
      <hardwareInterface>hardware_interface/PositionJointInterface</hardwareInterface>
    </actuator>
  </transmission>
  <link name="right_gripper_base">
    <inertial>
      <mass value="2e-06"/>
      <inertia ixx="1.1e-09" ixy="0" ixz="0" iyy="1.1e-09" iyz="0" izz="1.1e-09"/>
    </inertial>
  </link>
  <joint name="right_gripper_to_flange" type="fixed">
    <parent link="articulation_end_effector_right"/>
    <child link="right_gripper_base"/>
  </joint>
  <joint name="right_gripper_controller" type="revolute">
    <vc_robot_controller side="right" type="grippers"/>
    <vc_robot_controller side="right" type="gripper_action"/>
    <axis xyz="0 0 1"/>
    <limit effort="1000.0" lower="0.0" upper="0.548" velocity="0.5"/>
    <origin rpy="0 0 0" xyz="0.007 0.01 0"/>
    <parent link="right_gripper_base"/>
    <child link="right_up_gripper"/>
    <dynamics damping="5"/>
  </joint>
  <joint name="right_up_gripper_tip_joint" type="fixed">
    <parent link="right_up_gripper"/>
    <child link="right_up_gripper_tip"/>
    <dynamics damping="5"/>
  </joint>
  <joint name="right_down_gripper_joint" type="revolute">
    <vc_robot_controller side="right" type="gripper_mimic"/>
    <axis xyz="0 0 -1"/>
    <limit effort="1000.0" lower="0.0" upper="0.548" velocity="0.5"/>
    <origin rpy="0 0 0" xyz="0.007 -0.01 0"/>
    <parent link="right_gripper_base"/>
    <child link="right_down_gripper"/>
    <dynamics damping="5"/>
    <mimic joint="right_gripper_controller" multiplier="1.0" offset="0"/>
  </joint>
  <joint name="right_down_gripper_tip_joint" type="fixed">
    <parent link="right_down_gripper"/>
    <child link="right_down_gripper_tip"/>
    <dynamics damping="5"/>
  </joint>
  <transmission name="trans_right_gripper_controller">
    <type>transmission_interface/SimpleTransmission</type>
    <joint name="right_gripper_controller_joint" role="right_gripper_controller_joint">
      <hardwareInterface>hardware_interface/PositionJointInterface</hardwareInterface>
    </joint>
    <actuator name="actuator_right_gripper_controller" role="actuator_right_gripper_controller">
      <mechanicalReduction>1</mechanicalReduction>
      <hardwareInterface>hardware_interface/PositionJointInterface</hardwareInterface>
    </actuator>
  </transmission>
  <link name="base_link"/>
  <link name="chassis">
    <visual>
      <origin xyz="0.3 0 0.025"/>
      <geometry>
        <box size="0.6 0.4 0.05"/>
      </geometry>
      <material name="YellowOne"/>
      <meta>
        <layer> 1 </layer>
      </meta>
    </visual>
    <collision>
      <origin xyz="0.3 0 0.025"/>
      <geometry>
        <box size="0.6 0.4 0.05"/>
      </geometry>
    </collision>
    <inertial>
      <origin xyz="0.3 0 0.025"/>
      <mass value="0.5"/>
      <inertia ixx="0.006770833333333334" ixy="0.0" ixz="0.0" iyy="0.015104166666666665" iyz="0.0" izz="0.021666666666666667"/>
    </inertial>
  </link>
  <gazebo reference="chassis">
    <material>Gazebo/Blue</material>
    <material>Gazebo/Yellow</material>
  </gazebo>
  <joint name="chassis_joint" type="fixed">
    <parent link="base_link"/>
    <child link="chassis"/>
    <origin xyz="-0.3 0 0.025"/>
  </joint>
  <joint name="front_axle_chassis_joint" type="fixed">
    <parent link="chassis"/>
    <child link="front_axle"/>
    <origin rpy="1.5707963267948966 0 0" xyz="0.525 0 0"/>
  </joint>
  <joint name="back_axle_chassis_joint" type="fixed">
    <parent link="chassis"/>
    <child link="back_axle"/>
    <origin rpy="1.5707963267948966 0 0" xyz="0.075 0 0"/>
  </joint>
  <joint name="hfront_chassis_joint" type="fixed">
    <parent link="chassis"/>
    <child link="hood_front"/>
    <origin xyz="0.6 0 0.05"/>
  </joint>
  <joint name="hleft_chassis_joint" type="fixed">
    <parent link="chassis"/>
    <child link="hood_left"/>
    <origin xyz="0.5189189189189188 0.2 0.05"/>
  </joint>
  <joint name="hright_chassis_joint" type="fixed">
    <parent link="chassis"/>
    <child link="hood_right"/>
    <origin xyz="0.5189189189189188 -0.2 0.05"/>
  </joint>
  <joint name="htop_hfront_joint" type="fixed">
    <parent link="hood_front"/>
    <child link="hood_top"/>
    <origin xyz="-0.08108108108108107 0 0.2"/>
  </joint>
  <joint name="hbaffle_htop_joint" type="fixed">
    <parent link="hood_top"/>
    <child link="hood_baffle"/>
    <origin xyz="-0.040540540540540536 0 0.05"/>
  </joint>
  <joint name="bladle_hfront_joint" type="fixed">
    <parent link="hood_front"/>
    <child link="box_ladle_front"/>
    <origin xyz="0 0 0.04"/>
  </joint>
  <joint name="lbracket_holder_bladle_joint" type="fixed">
    <parent link="box_ladle_front"/>
    <child link="box_bracket_holder_left"/>
    <origin xyz="0.0225 0.15500000000000003 0"/>
  </joint>
  <joint name="rbracket_holder_bladle_joint" type="fixed">
    <parent link="box_ladle_front"/>
    <child link="box_bracket_holder_right"/>
    <origin xyz="0.0225 -0.15500000000000003 0"/>
  </joint>
  <joint name="pback_chassis_joint" type="fixed">
    <parent link="chassis"/>
    <child link="box_panel_back"/>
    <origin xyz="0.015 0 0.05"/>
  </joint>
  <joint name="pfront_chassis_joint" type="fixed">
    <parent link="chassis"/>
    <child link="box_panel_front"/>
    <origin xyz="0.4378378378378378 0 0.05"/>
  </joint>
  <joint name="pleft_chassis_joint" type="fixed">
    <parent link="chassis"/>
    <child link="box_panel_left"/>
    <origin xyz="0.2189189189189189 0.2 0.05"/>
  </joint>
  <joint name="pright_chassis_joint" type="fixed">
    <parent link="chassis"/>
    <child link="box_panel_right"/>
    <origin xyz="0.2189189189189189 -0.2 0.05"/>
  </joint>
  <joint name="ptop_pfront_joint" type="fixed">
    <parent link="box_panel_front"/>
    <child link="box_panel_top"/>
    <origin xyz="-0.14594594594594593 0 0.3"/>
  </joint>
  <joint name="hinge_pback_joint" type="fixed">
    <parent link="box_panel_back"/>
    <child link="hinge_cover"/>
    <origin rpy="1.5707963267948966 0 0" xyz="0 0 0.32"/>
  </joint>
  <joint name="cover_hinge_joint" type="revolute">
    <vc_robot_controller type="covers"/>
    <parent link="hinge_cover"/>
    <child link="box_cover"/>
    <axis xyz="0 1 0"/>
    <origin rpy="1.5707963267948966 0 0" xyz="0 0 0"/>
    <limit effort="100.0" lower="0.0" upper="1.3" velocity="0.5"/>
  </joint>
  <transmission name="transmission_cover_hinge">
    <plugin>transmission_interface/SimpleTransmission</plugin>
    <actuator name="actuator_cover_hinge" role="actuator_cover_hinge"/>
    <joint name="cover_hinge_joint" role="cover_hinge_joint">
      <mechanical_reduction>1.0</mechanical_reduction>
    </joint>
  </transmission>
  <joint name="bgripper_pleft_joint" type="fixed">
    <parent link="box_panel_left"/>
    <child link="box_gripper_left"/>
    <origin xyz="0 0 0.15"/>
  </joint>
  <joint name="bgripper_holder_pleft_joint" type="fixed">
    <parent link="box_gripper_left"/>
    <child link="box_gripper_holder_left"/>
    <origin xyz="0 0.0075 0"/>
  </joint>
  <joint name="bgripper_pright_joint" type="fixed">
    <parent link="box_panel_right"/>
    <child link="box_gripper_right"/>
    <origin xyz="0 0 0.15"/>
  </joint>
  <joint name="bgripper_holder_pright_joint" type="fixed">
    <parent link="box_gripper_right"/>
    <child link="box_gripper_holder_right"/>
    <origin xyz="0 -0.0075 0"/>
  </joint>
  <joint name="front_left_wheel_joint" type="continuous">
    <vc_robot_controller side="left" type="differential_drive"/>
    <parent link="front_axle"/>
    <child link="front_left_wheel"/>
    <origin rpy="3.141592653589793 0 0" xyz="0 0 -0.23"/>
    <axis xyz="0 0 1"/>
  </joint>
  <joint name="front_right_wheel_joint" type="continuous">
    <vc_robot_controller side="right" type="differential_drive"/>
    <parent link="front_axle"/>
    <child link="front_right_wheel"/>
    <origin xyz="0 0 0.23"/>
    <axis xyz="0 0 -1"/>
  </joint>
  <joint name="back_left_wheel_joint" type="continuous">
    <vc_robot_controller side="left" type="differential_drive"/>
    <parent link="back_axle"/>
    <child link="back_left_wheel"/>
    <origin rpy="3.141592653589793 0 0" xyz="0 0 -0.23"/>
    <axis xyz="0 0 1"/>
  </joint>
  <joint name="back_right_wheel_joint" type="continuous">
    <vc_robot_controller side="right" type="differential_drive"/>
    <parent link="back_axle"/>
    <child link="back_right_wheel"/>
    <origin xyz="0 0 0.23"/>
    <axis xyz="0 0 -1"/>
  </joint>
  <gazebo reference="front_axle">
    <material>Gazebo/White</material>
  </gazebo>
  <gazebo reference="back_axle">
    <material>Gazebo/White</material>
  </gazebo>
  <gazebo reference="box_panel_front">
    <material>Gazebo/Yellow</material>
  </gazebo>
  <gazebo reference="box_panel_top">
    <material>Gazebo/Yellow</material>
  </gazebo>
  <gazebo reference="hinge_cover">
    <material>Gazebo/Green</material>
  </gazebo>
  <gazebo reference="box_cover">
    <material>Gazebo/Green</material>
  </gazebo>
  <gazebo reference="box_gripper_left">
    <material>Gazebo/Yellow</material>
  </gazebo>
  <gazebo reference="box_gripper_right">
    <material>Gazebo/Yellow</material>
  </gazebo>
  <gazebo reference="hood_left">
    <material>Gazebo/Orange</material>
  </gazebo>
  <gazebo reference="hood_right">
    <material>Gazebo/Orange</material>
  </gazebo>
  <gazebo reference="hood_front">
    <material>Gazebo/Orange</material>
  </gazebo>
  <gazebo reference="hood_top">
    <material>Gazebo/Orange</material>
  </gazebo>
  <gazebo reference="hood_baffle">
    <material>Gazebo/GreyTransparent</material>
  </gazebo>
  <gazebo reference="box_ladle_front">
    <material>Gazebo/Green</material>
  </gazebo>
  <gazebo reference="box_bracket_holder_left">
    <material>Gazebo/Red</material>
  </gazebo>
  <gazebo reference="box_bracket_holder_right">
    <material>Gazebo/Red</material>
  </gazebo>
  <gazebo reference="front_lidar_box">
    <material>Gazebo/Grey</material>
  </gazebo>
  <gazebo reference="back_lidar_box">
    <material>Gazebo/Grey</material>
  </gazebo>
</robot>
